

------------------------------
2010-07-27 10:47:07.506000
------------------------------



------------------------------
2010-12-08 12:02:02.904000
------------------------------

Traceback (most recent call last):

------------------------------
2010-12-08 12:02:02.966000
------------------------------

  File "L:\python\libs\pyview\ide\codeeditor.py", line 70, in killThread
    self.Tab.currentWidget().killThread()
  File "L:\python\libs\pyview\ide\codeeditor.py", line 456, in killThread
    self.thread.terminate()
  File "L:\python\libs\pyview\lib\patterns.py", line 51, in terminate
    self.raise_exc(SystemExit)
  File "L:\python\libs\pyview\lib\patterns.py", line 38, in raise_exc
    assert self.isAlive(), "thread must be started"
AssertionError: thread must be started
Traceback (most recent call last):
  File "L:\python\libs\pyview\ide\codeeditor.py", line 70, in killThread
    self.Tab.currentWidget().killThread()
  File "L:\python\libs\pyview\ide\codeeditor.py", line 456, in killThread
    self.thread.terminate()
  File "L:\python\libs\pyview\lib\patterns.py", line 51, in terminate
    self.raise_exc(SystemExit)
  File "L:\python\libs\pyview\lib\patterns.py", line 38, in raise_exc
    assert self.isAlive(), "thread must be started"
AssertionError: thread must be started
Traceback (most recent call last):
  File "L:\python\libs\pyview\ide\codeeditor.py", line 33, in run
    exec(self.code,self._gv,self._gv)
  File "<string>", line 82, in <module>
  File "<string>", line 31, in createMeasurement
  File "C:\Python26\lib\site-packages\numpy\linalg\linalg.py", line 893, in eigh
    a = _fastCopyAndTranspose(t, a)
  File "C:\Python26\lib\site-packages\numpy\linalg\linalg.py", line 98, in _fastCopyAndTranspose
    cast_arrays = cast_arrays + (_fastCT(a.astype(type)),)
SystemExit
Traceback (most recent call last):
  File "L:\python\libs\pyview\ide\codeeditor.py", line 70, in killThread
    self.Tab.currentWidget().killThread()
  File "L:\python\libs\pyview\ide\codeeditor.py", line 456, in killThread
    self.thread.terminate()
  File "L:\python\libs\pyview\lib\patterns.py", line 51, in terminate
    self.raise_exc(SystemExit)
  File "L:\python\libs\pyview\lib\patterns.py", line 38, in raise_exc
    assert self.isAlive(), "thread must be started"
AssertionError: thread must be started
Traceback (most recent call last):
  File "L:\python\libs\pyview\ide\codeeditor.py", line 33, in run
    exec(self.code,self._gv,self._gv)
  File "<string>", line 82, in <module>
  File "<string>", line 42, in createMeasurement
  File "C:\Python26\lib\site-packages\numpy\core\defmatrix.py", line 265, in __getitem__
    out = N.ndarray.__getitem__(self, index)
  File "C:\Python26\lib\site-packages\numpy\core\defmatrix.py", line 241, in __array_finalize__
    if (isinstance(obj, matrix) and obj._getitem): return
SystemExit
Traceback (most recent call last):

------------------------------
2010-12-08 12:03:04.655000
------------------------------

  File "L:\python\libs\pyview\ide\codeeditor.py", line 70, in killThread
    self.Tab.currentWidget().killThread()
  File "L:\python\libs\pyview\ide\codeeditor.py", line 456, in killThread
    self.thread.terminate()
  File "L:\python\libs\pyview\lib\patterns.py", line 51, in terminate
    self.raise_exc(SystemExit)
  File "L:\python\libs\pyview\lib\patterns.py", line 38, in raise_exc
    assert self.isAlive(), "thread must be started"
AssertionError: thread must be started
Traceback (most recent call last):
  File "L:\python\libs\pyview\ide\codeeditor.py", line 70, in killThread
    self.Tab.currentWidget().killThread()
  File "L:\python\libs\pyview\ide\codeeditor.py", line 456, in killThread
    self.thread.terminate()
  File "L:\python\libs\pyview\lib\patterns.py", line 51, in terminate
    self.raise_exc(SystemExit)
  File "L:\python\libs\pyview\lib\patterns.py", line 38, in raise_exc
    assert self.isAlive(), "thread must be started"
AssertionError: thread must be started
Traceback (most recent call last):
  File "L:\python\libs\pyview\ide\codeeditor.py", line 33, in run
    exec(self.code,self._gv,self._gv)
  File "<string>", line 92, in <module>
  File "C:\Python26\lib\site-packages\numpy\core\fromnumeric.py", line 399, in transpose
    return transpose(axes)
  File "C:\Python26\lib\site-packages\numpy\core\defmatrix.py", line 241, in __array_finalize__
    if (isinstance(obj, matrix) and obj._getitem): return
SystemExit
Traceback (most recent call last):

------------------------------
2010-12-08 12:04:07.531000
------------------------------

  File "L:\python\libs\pyview\ide\codeeditor.py", line 70, in killThread
    self.Tab.currentWidget().killThread()
  File "L:\python\libs\pyview\ide\codeeditor.py", line 456, in killThread
    self.thread.terminate()
  File "L:\python\libs\pyview\lib\patterns.py", line 51, in terminate
    self.raise_exc(SystemExit)
  File "L:\python\libs\pyview\lib\patterns.py", line 38, in raise_exc
    assert self.isAlive(), "thread must be started"
AssertionError: thread must be started
Traceback (most recent call last):
  File "L:\python\libs\pyview\ide\codeeditor.py", line 70, in killThread
    self.Tab.currentWidget().killThread()
  File "L:\python\libs\pyview\ide\codeeditor.py", line 456, in killThread
    self.thread.terminate()
  File "L:\python\libs\pyview\lib\patterns.py", line 51, in terminate
    self.raise_exc(SystemExit)
  File "L:\python\libs\pyview\lib\patterns.py", line 38, in raise_exc
    assert self.isAlive(), "thread must be started"
AssertionError: thread must be started
Traceback (most recent call last):
  File "L:\python\libs\pyview\ide\codeeditor.py", line 33, in run
    exec(self.code,self._gv,self._gv)
  File "<string>", line 82, in <module>
  File "<string>", line 31, in createMeasurement
  File "C:\Python26\lib\site-packages\numpy\linalg\linalg.py", line 890, in eigh
    _assertSquareness(a)
  File "C:\Python26\lib\site-packages\numpy\linalg\linalg.py", line 112, in _assertSquareness
    if max(a.shape) != min(a.shape):
SystemExit
Exception in thread Thread-108046:

------------------------------
2010-12-08 12:06:34.565000
------------------------------

Traceback (most recent call last):
  File "C:\Python26\lib\threading.py", line 525, in __bootstrap_inner
    self.run()
  File "L:\python\libs\pyview\ide\codeeditor.py", line 33, in run
    exec(self.code,self._gv,self._gv)
  File "<string>", line 7, in <module>
ValueError: shape mismatch: objects cannot be broadcast to a single shape

Traceback (most recent call last):
  File "L:\python\libs\pyview\ide\codeeditor.py", line 33, in run
    exec(self.code,self._gv,self._gv)
  File "<string>", line 7, in <module>
ValueError: shape mismatch: objects cannot be broadcast to a single shape
Exception in thread Thread-108051:
Traceback (most recent call last):
  File "C:\Python26\lib\threading.py", line 525, in __bootstrap_inner
    self.run()
  File "L:\python\libs\pyview\ide\codeeditor.py", line 33, in run
    exec(self.code,self._gv,self._gv)
  File "<string>", line 7, in <module>
ValueError: shape mismatch: objects cannot be broadcast to a single shape

Traceback (most recent call last):
  File "L:\python\libs\pyview\ide\codeeditor.py", line 33, in run
    exec(self.code,self._gv,self._gv)
  File "<string>", line 7, in <module>
ValueError: shape mismatch: objects cannot be broadcast to a single shape
Exception in thread Thread-108054:
Traceback (most recent call last):
  File "C:\Python26\lib\threading.py", line 525, in __bootstrap_inner
    self.run()
  File "L:\python\libs\pyview\ide\codeeditor.py", line 33, in run
    exec(self.code,self._gv,self._gv)
  File "<string>", line 7, in <module>
ValueError: shape mismatch: objects cannot be broadcast to a single shape

Traceback (most recent call last):
  File "L:\python\libs\pyview\ide\codeeditor.py", line 33, in run
    exec(self.code,self._gv,self._gv)
  File "<string>", line 7, in <module>
ValueError: shape mismatch: objects cannot be broadcast to a single shape
Exception in thread Thread-108058:
Traceback (most recent call last):
  File "C:\Python26\lib\threading.py", line 525, in __bootstrap_inner
    self.run()
  File "L:\python\libs\pyview\ide\codeeditor.py", line 33, in run
    exec(self.code,self._gv,self._gv)
  File "<string>", line 1
    Setting up code environment...
             ^
SyntaxError: invalid syntax

Traceback (most recent call last):
  File "L:\python\libs\pyview\ide\codeeditor.py", line 33, in run
    exec(self.code,self._gv,self._gv)
  File "<string>", line 1
     Setting up code environment...
              ^
 SyntaxError: invalid syntax
Exception in thread Thread-108059:
Traceback (most recent call last):
  File "C:\Python26\lib\threading.py", line 525, in __bootstrap_inner
    self.run()
  File "L:\python\libs\pyview\ide\codeeditor.py", line 33, in run
    exec(self.code,self._gv,self._gv)
  File "<string>", line 7, in <module>
ValueError: shape mismatch: objects cannot be broadcast to a single shape

Traceback (most recent call last):
  File "L:\python\libs\pyview\ide\codeeditor.py", line 33, in run
    exec(self.code,self._gv,self._gv)
  File "<string>", line 7, in <module>
ValueError: shape mismatch: objects cannot be broadcast to a single shape
Traceback (most recent call last):

------------------------------
2010-12-08 12:08:06.942000
------------------------------

  File "L:\python\libs\pyview\ide\codeeditor.py", line 33, in run
    exec(self.code,self._gv,self._gv)
  File "<string>", line 41, in <module>
  File "L:\python\libs\pyview\ide\gui.pyw", line 76, in write
    self._callback(text)
  File "L:\python\libs\pyview\ide\gui.pyw", line 138, in writeStdout
    self.queuedStdoutText += text
SystemExit
Exception in thread Thread-108077:
Traceback (most recent call last):
  File "C:\Python26\lib\threading.py", line 525, in __bootstrap_inner
    self.run()
  File "L:\python\libs\pyview\ide\codeeditor.py", line 33, in run
    exec(self.code,self._gv,self._gv)
  File "<string>", line 15, in <module>
  File "<string>", line 31, in fitDensityMatrix
TypeError: fmin_bfgs() got an unexpected keyword argument 'maxfun'

Traceback (most recent call last):
  File "L:\python\libs\pyview\ide\codeeditor.py", line 33, in run
    exec(self.code,self._gv,self._gv)
  File "<string>", line 15, in <module>
  File "<string>", line 31, in fitDensityMatrix
TypeError: fmin_bfgs() got an unexpected keyword argument 'maxfun'
Traceback (most recent call last):

------------------------------
2010-12-08 12:09:27.803000
------------------------------

  File "L:\python\libs\pyview\ide\codeeditor.py", line 70, in killThread
    self.Tab.currentWidget().killThread()
  File "L:\python\libs\pyview\ide\codeeditor.py", line 456, in killThread
    self.thread.terminate()
  File "L:\python\libs\pyview\lib\patterns.py", line 51, in terminate
    self.raise_exc(SystemExit)
  File "L:\python\libs\pyview\lib\patterns.py", line 38, in raise_exc
    assert self.isAlive(), "thread must be started"
AssertionError: thread must be started
Traceback (most recent call last):
  File "L:\python\libs\pyview\ide\codeeditor.py", line 33, in run
    exec(self.code,self._gv,self._gv)
  File "<string>", line 15, in <module>
  File "<string>", line 31, in fitDensityMatrix
  File "C:\Python26\lib\site-packages\scipy\optimize\optimize.py", line 205, in fmin
    fxr = func(xr)
  File "C:\Python26\lib\site-packages\scipy\optimize\optimize.py", line 97, in function_wrapper
    return function(x, *args)
  File "<string>", line 15, in error_function
  File "<string>", line 10, in generate_rho
  File "C:\Python26\lib\site-packages\numpy\core\fromnumeric.py", line 901, in trace
    return asarray(a).trace(offset, axis1, axis2, dtype, out)
  File "C:\Python26\lib\site-packages\numpy\core\numeric.py", line 180, in asarray
    def asarray(a, dtype=None, order=None):
SystemExit
Traceback (most recent call last):

------------------------------
2010-12-08 12:12:06.540000
------------------------------

  File "L:\python\libs\pyview\ide\codeeditor.py", line 70, in killThread
    self.Tab.currentWidget().killThread()
  File "L:\python\libs\pyview\ide\codeeditor.py", line 456, in killThread
    self.thread.terminate()
  File "L:\python\libs\pyview\lib\patterns.py", line 51, in terminate
    self.raise_exc(SystemExit)
  File "L:\python\libs\pyview\lib\patterns.py", line 38, in raise_exc
    assert self.isAlive(), "thread must be started"
AssertionError: thread must be started
Traceback (most recent call last):
  File "L:\python\libs\pyview\ide\codeeditor.py", line 70, in killThread
    self.Tab.currentWidget().killThread()
  File "L:\python\libs\pyview\ide\codeeditor.py", line 456, in killThread
    self.thread.terminate()
  File "L:\python\libs\pyview\lib\patterns.py", line 51, in terminate
    self.raise_exc(SystemExit)
  File "L:\python\libs\pyview\lib\patterns.py", line 38, in raise_exc
    assert self.isAlive(), "thread must be started"
AssertionError: thread must be started
Traceback (most recent call last):
  File "L:\python\libs\pyview\ide\codeeditor.py", line 70, in killThread
    self.Tab.currentWidget().killThread()
  File "L:\python\libs\pyview\ide\codeeditor.py", line 456, in killThread
    self.thread.terminate()
  File "L:\python\libs\pyview\lib\patterns.py", line 51, in terminate
    self.raise_exc(SystemExit)
  File "L:\python\libs\pyview\lib\patterns.py", line 38, in raise_exc
    assert self.isAlive(), "thread must be started"
AssertionError: thread must be started
Traceback (most recent call last):
  File "L:\python\libs\pyview\ide\codeeditor.py", line 70, in killThread
    self.Tab.currentWidget().killThread()
  File "L:\python\libs\pyview\ide\codeeditor.py", line 456, in killThread
    self.thread.terminate()
  File "L:\python\libs\pyview\lib\patterns.py", line 51, in terminate
    self.raise_exc(SystemExit)
  File "L:\python\libs\pyview\lib\patterns.py", line 38, in raise_exc
    assert self.isAlive(), "thread must be started"
AssertionError: thread must be started
Traceback (most recent call last):
  File "L:\python\libs\pyview\ide\codeeditor.py", line 33, in run
    exec(self.code,self._gv,self._gv)
  File "<string>", line 15, in <module>
  File "<string>", line 31, in fitDensityMatrix
  File "C:\Python26\lib\site-packages\scipy\optimize\optimize.py", line 1754, in fmin_powell
    fval, x, direc1 = _linesearch_powell(func, x, direc1, tol=xtol*100)
  File "C:\Python26\lib\site-packages\scipy\optimize\optimize.py", line 1653, in _linesearch_powell
    alpha_min, fret, iter, num = brent(myfunc, full_output=1, tol=tol)
  File "C:\Python26\lib\site-packages\scipy\optimize\optimize.py", line 1475, in brent
    brent.optimize()
  File "C:\Python26\lib\site-packages\scipy\optimize\optimize.py", line 1400, in optimize
    fu = func(*((u,)+self.args))      # calculate new output value
  File "C:\Python26\lib\site-packages\scipy\optimize\optimize.py", line 1652, in myfunc
    return func(p + alpha * xi)
  File "C:\Python26\lib\site-packages\scipy\optimize\optimize.py", line 97, in function_wrapper
    return function(x, *args)
  File "<string>", line 15, in error_function
  File "<string>", line 3, in generate_rho
  File "C:\Python26\lib\site-packages\numpy\core\defmatrix.py", line 210, in __new__
    if copy: return new.copy()
  File "C:\Python26\lib\site-packages\numpy\core\defmatrix.py", line 240, in __array_finalize__
    self._getitem = False
SystemExit
Traceback (most recent call last):

------------------------------
2010-12-08 12:14:16.855000
------------------------------

  File "L:\python\libs\pyview\ide\codeeditor.py", line 70, in killThread
    self.Tab.currentWidget().killThread()
  File "L:\python\libs\pyview\ide\codeeditor.py", line 456, in killThread
    self.thread.terminate()
  File "L:\python\libs\pyview\lib\patterns.py", line 51, in terminate
    self.raise_exc(SystemExit)
  File "L:\python\libs\pyview\lib\patterns.py", line 38, in raise_exc
    assert self.isAlive(), "thread must be started"
AssertionError: thread must be started
Traceback (most recent call last):
  File "L:\python\libs\pyview\ide\codeeditor.py", line 33, in run
    exec(self.code,self._gv,self._gv)
  File "<string>", line 15, in <module>
  File "<string>", line 31, in fitDensityMatrix
  File "C:\Python26\lib\site-packages\scipy\optimize\optimize.py", line 1754, in fmin_powell
    fval, x, direc1 = _linesearch_powell(func, x, direc1, tol=xtol*100)
  File "C:\Python26\lib\site-packages\scipy\optimize\optimize.py", line 1653, in _linesearch_powell
    alpha_min, fret, iter, num = brent(myfunc, full_output=1, tol=tol)
  File "C:\Python26\lib\site-packages\scipy\optimize\optimize.py", line 1475, in brent
    brent.optimize()
  File "C:\Python26\lib\site-packages\scipy\optimize\optimize.py", line 1400, in optimize
    fu = func(*((u,)+self.args))      # calculate new output value
  File "C:\Python26\lib\site-packages\scipy\optimize\optimize.py", line 1652, in myfunc
    return func(p + alpha * xi)
  File "C:\Python26\lib\site-packages\scipy\optimize\optimize.py", line 97, in function_wrapper
    return function(x, *args)
  File "<string>", line 22, in error_function
SystemExit
Traceback (most recent call last):

------------------------------
2010-12-08 12:16:31.858000
------------------------------

  File "L:\python\libs\pyview\ide\codeeditor.py", line 33, in run
    exec(self.code,self._gv,self._gv)
  File "<string>", line 15, in <module>
  File "<string>", line 32, in fitDensityMatrix
  File "C:\Python26\lib\site-packages\scipy\optimize\optimize.py", line 1754, in fmin_powell
    fval, x, direc1 = _linesearch_powell(func, x, direc1, tol=xtol*100)
  File "C:\Python26\lib\site-packages\scipy\optimize\optimize.py", line 1653, in _linesearch_powell
    alpha_min, fret, iter, num = brent(myfunc, full_output=1, tol=tol)
  File "C:\Python26\lib\site-packages\scipy\optimize\optimize.py", line 1475, in brent
    brent.optimize()
  File "C:\Python26\lib\site-packages\scipy\optimize\optimize.py", line 1400, in optimize
    fu = func(*((u,)+self.args))      # calculate new output value
  File "C:\Python26\lib\site-packages\scipy\optimize\optimize.py", line 1652, in myfunc
    return func(p + alpha * xi)
  File "C:\Python26\lib\site-packages\scipy\optimize\optimize.py", line 97, in function_wrapper
    return function(x, *args)
  File "<string>", line 19, in error_function
  File "C:\Python26\lib\site-packages\numpy\core\defmatrix.py", line 290, in __mul__
    return N.dot(self, asmatrix(other))
  File "C:\Python26\lib\site-packages\numpy\core\defmatrix.py", line 241, in __array_finalize__
    if (isinstance(obj, matrix) and obj._getitem): return
SystemExit
<string>:48: DeprecationWarning: integer argument expected, got float

------------------------------
2010-12-08 12:19:04.501000
------------------------------

Traceback (most recent call last):
  File "L:\python\libs\pyview\ide\codeeditor.py", line 70, in killThread
    self.Tab.currentWidget().killThread()
  File "L:\python\libs\pyview\ide\codeeditor.py", line 456, in killThread
    self.thread.terminate()
  File "L:\python\libs\pyview\lib\patterns.py", line 51, in terminate
    self.raise_exc(SystemExit)
  File "L:\python\libs\pyview\lib\patterns.py", line 38, in raise_exc
    assert self.isAlive(), "thread must be started"
AssertionError: thread must be started
Traceback (most recent call last):
  File "L:\python\libs\pyview\ide\codeeditor.py", line 70, in killThread
    self.Tab.currentWidget().killThread()
  File "L:\python\libs\pyview\ide\codeeditor.py", line 456, in killThread
    self.thread.terminate()
  File "L:\python\libs\pyview\lib\patterns.py", line 51, in terminate
    self.raise_exc(SystemExit)
  File "L:\python\libs\pyview\lib\patterns.py", line 38, in raise_exc
    assert self.isAlive(), "thread must be started"
AssertionError: thread must be started
Traceback (most recent call last):
  File "L:\python\libs\pyview\ide\codeeditor.py", line 33, in run
    exec(self.code,self._gv,self._gv)
  File "<string>", line 83, in <module>
  File "<string>", line 48, in createMeasurement
  File "C:\Python26\lib\site-packages\numpy\core\defmatrix.py", line 241, in __array_finalize__
    if (isinstance(obj, matrix) and obj._getitem): return
SystemExit
Traceback (most recent call last):

------------------------------
2010-12-08 12:21:31.239000
------------------------------

  File "L:\python\libs\pyview\ide\codeeditor.py", line 33, in run
    exec(self.code,self._gv,self._gv)
  File "<string>", line 82, in <module>
SystemExit
Exception in thread Thread-108251:
Traceback (most recent call last):
  File "C:\Python26\lib\threading.py", line 525, in __bootstrap_inner
    self.run()
  File "L:\python\libs\pyview\ide\codeeditor.py", line 33, in run
    exec(self.code,self._gv,self._gv)
  File "<string>", line 7, in <module>
ValueError: shape mismatch: objects cannot be broadcast to a single shape

Traceback (most recent call last):
  File "L:\python\libs\pyview\ide\codeeditor.py", line 33, in run
    exec(self.code,self._gv,self._gv)
  File "<string>", line 7, in <module>
ValueError: shape mismatch: objects cannot be broadcast to a single shape
Traceback (most recent call last):

------------------------------
2010-12-08 12:24:48.008000
------------------------------

  File "L:\python\libs\pyview\ide\codeeditor.py", line 33, in run
    exec(self.code,self._gv,self._gv)
  File "<string>", line 15, in <module>
  File "<string>", line 32, in fitDensityMatrix
  File "C:\Python26\lib\site-packages\scipy\optimize\optimize.py", line 1754, in fmin_powell
    fval, x, direc1 = _linesearch_powell(func, x, direc1, tol=xtol*100)
  File "C:\Python26\lib\site-packages\scipy\optimize\optimize.py", line 1653, in _linesearch_powell
    alpha_min, fret, iter, num = brent(myfunc, full_output=1, tol=tol)
  File "C:\Python26\lib\site-packages\scipy\optimize\optimize.py", line 1475, in brent
    brent.optimize()
  File "C:\Python26\lib\site-packages\scipy\optimize\optimize.py", line 1400, in optimize
    fu = func(*((u,)+self.args))      # calculate new output value
  File "C:\Python26\lib\site-packages\scipy\optimize\optimize.py", line 1652, in myfunc
    return func(p + alpha * xi)
  File "C:\Python26\lib\site-packages\scipy\optimize\optimize.py", line 97, in function_wrapper
    return function(x, *args)
  File "<string>", line 15, in error_function
  File "<string>", line 8, in generate_rho
SystemExit
<string>:50: DeprecationWarning: integer argument expected, got float
Traceback (most recent call last):

------------------------------
2010-12-08 12:25:59.884000
------------------------------

  File "L:\python\libs\pyview\ide\codeeditor.py", line 33, in run
    exec(self.code,self._gv,self._gv)
  File "<string>", line 85, in <module>
  File "<string>", line 48, in createMeasurement
SystemExit
Exception in thread Thread-108341:

------------------------------
2010-12-08 12:28:31.356000
------------------------------

Traceback (most recent call last):
  File "C:\Python26\lib\threading.py", line 525, in __bootstrap_inner
    self.run()
  File "L:\python\libs\pyview\ide\codeeditor.py", line 33, in run
    exec(self.code,self._gv,self._gv)
  File "<string>", line 51, in <module>
NameError: name 'measuedSpins' is not defined

Traceback (most recent call last):
  File "L:\python\libs\pyview\ide\codeeditor.py", line 33, in run
    exec(self.code,self._gv,self._gv)
  File "<string>", line 51, in <module>
NameError: name 'measuedSpins' is not defined
Exception in thread Thread-108387:

------------------------------
2010-12-08 12:32:09.126000
------------------------------

Traceback (most recent call last):
  File "C:\Python26\lib\threading.py", line 525, in __bootstrap_inner
    self.run()
  File "L:\python\libs\pyview\ide\codeeditor.py", line 33, in run
    exec(self.code,self._gv,self._gv)
  File "<string>", line 100
    cube.set(**{mlabel+"p1x":measuredVector[0]+measuredVector[1]})
       ^
SyntaxError: invalid syntax

Traceback (most recent call last):
  File "L:\python\libs\pyview\ide\codeeditor.py", line 33, in run
    exec(self.code,self._gv,self._gv)
  File "<string>", line 100
     cube.set(**{mlabel+"p1x":measuredVector[0]+measuredVector[1]})
        ^
 SyntaxError: invalid syntax
Exception in thread Thread-108390:
Traceback (most recent call last):
  File "C:\Python26\lib\threading.py", line 525, in __bootstrap_inner
    self.run()
  File "L:\python\libs\pyview\ide\codeeditor.py", line 33, in run
    exec(self.code,self._gv,self._gv)
  File "<string>", line 99, in <module>
  File "L:\python\libs\pyview\lib\datacube.py", line 357, in set
    self._table[self._index,i] = keywords[keyword]
ValueError: setting an array element with a sequence.

Traceback (most recent call last):
  File "L:\python\libs\pyview\ide\codeeditor.py", line 33, in run
    exec(self.code,self._gv,self._gv)
  File "<string>", line 99, in <module>
  File "L:\python\libs\pyview\lib\datacube.py", line 357, in set
    self._table[self._index,i] = keywords[keyword]
ValueError: setting an array element with a sequence.
Exception in thread Thread-108394:
Traceback (most recent call last):
  File "C:\Python26\lib\threading.py", line 525, in __bootstrap_inner
    self.run()
  File "L:\python\libs\pyview\ide\codeeditor.py", line 33, in run
    exec(self.code,self._gv,self._gv)
  File "<string>", line 99, in <module>
  File "C:\Python26\lib\site-packages\numpy\core\defmatrix.py", line 290, in __mul__
    return N.dot(self, asmatrix(other))
ValueError: matrices are not aligned

Traceback (most recent call last):
  File "L:\python\libs\pyview\ide\codeeditor.py", line 33, in run
    exec(self.code,self._gv,self._gv)
  File "<string>", line 99, in <module>
  File "C:\Python26\lib\site-packages\numpy\core\defmatrix.py", line 290, in __mul__
    return N.dot(self, asmatrix(other))
ValueError: matrices are not aligned
Exception in thread Thread-108397:
Traceback (most recent call last):
  File "C:\Python26\lib\threading.py", line 525, in __bootstrap_inner
    self.run()
  File "L:\python\libs\pyview\ide\codeeditor.py", line 33, in run
    exec(self.code,self._gv,self._gv)
  File "<string>", line 99, in <module>
  File "C:\Python26\lib\site-packages\numpy\core\defmatrix.py", line 290, in __mul__
    return N.dot(self, asmatrix(other))
ValueError: matrices are not aligned

Traceback (most recent call last):
  File "L:\python\libs\pyview\ide\codeeditor.py", line 33, in run
    exec(self.code,self._gv,self._gv)
  File "<string>", line 99, in <module>
  File "C:\Python26\lib\site-packages\numpy\core\defmatrix.py", line 290, in __mul__
    return N.dot(self, asmatrix(other))
ValueError: matrices are not aligned
Traceback (most recent call last):
  File "L:\python\libs\pyview\ide\codeeditor.py", line 70, in killThread
    self.Tab.currentWidget().killThread()
  File "L:\python\libs\pyview\ide\codeeditor.py", line 456, in killThread
    self.thread.terminate()
  File "L:\python\libs\pyview\lib\patterns.py", line 51, in terminate
    self.raise_exc(SystemExit)
  File "L:\python\libs\pyview\lib\patterns.py", line 38, in raise_exc
    assert self.isAlive(), "thread must be started"
AssertionError: thread must be started
Traceback (most recent call last):
  File "L:\python\libs\pyview\ide\codeeditor.py", line 33, in run
    exec(self.code,self._gv,self._gv)
  File "<string>", line 85, in <module>
  File "<string>", line 48, in createMeasurement
SystemExit
Traceback (most recent call last):

------------------------------
2010-12-08 12:40:43.046000
------------------------------

  File "L:\python\libs\pyview\ide\codeeditor.py", line 33, in run
    exec(self.code,self._gv,self._gv)
  File "<string>", line 86, in <module>
SystemExit
Traceback (most recent call last):

------------------------------
2010-12-08 12:49:01.542000
------------------------------

  File "L:\python\libs\pyview\ide\codeeditor.py", line 33, in run
    exec(self.code,self._gv,self._gv)
  File "<string>", line 15, in <module>
  File "<string>", line 32, in fitDensityMatrix
  File "C:\Python26\lib\site-packages\scipy\optimize\optimize.py", line 1754, in fmin_powell
    fval, x, direc1 = _linesearch_powell(func, x, direc1, tol=xtol*100)
  File "C:\Python26\lib\site-packages\scipy\optimize\optimize.py", line 1653, in _linesearch_powell
    alpha_min, fret, iter, num = brent(myfunc, full_output=1, tol=tol)
  File "C:\Python26\lib\site-packages\scipy\optimize\optimize.py", line 1475, in brent
    brent.optimize()
  File "C:\Python26\lib\site-packages\scipy\optimize\optimize.py", line 1400, in optimize
    fu = func(*((u,)+self.args))      # calculate new output value
  File "C:\Python26\lib\site-packages\scipy\optimize\optimize.py", line 1652, in myfunc
    return func(p + alpha * xi)
  File "C:\Python26\lib\site-packages\scipy\optimize\optimize.py", line 97, in function_wrapper
    return function(x, *args)
  File "<string>", line 19, in error_function
  File "C:\Python26\lib\site-packages\numpy\core\defmatrix.py", line 290, in __mul__
    return N.dot(self, asmatrix(other))
  File "C:\Python26\lib\site-packages\numpy\core\defmatrix.py", line 241, in __array_finalize__
    if (isinstance(obj, matrix) and obj._getitem): return
SystemExit
Traceback (most recent call last):

------------------------------
2010-12-08 12:53:10.589000
------------------------------

  File "L:\python\libs\pyview\ide\codeeditor.py", line 33, in run
    exec(self.code,self._gv,self._gv)
  File "<string>", line 15, in <module>
  File "<string>", line 31, in fitDensityMatrix
  File "C:\Python26\lib\site-packages\scipy\optimize\optimize.py", line 1754, in fmin_powell
    fval, x, direc1 = _linesearch_powell(func, x, direc1, tol=xtol*100)
  File "C:\Python26\lib\site-packages\scipy\optimize\optimize.py", line 1653, in _linesearch_powell
    alpha_min, fret, iter, num = brent(myfunc, full_output=1, tol=tol)
  File "C:\Python26\lib\site-packages\scipy\optimize\optimize.py", line 1475, in brent
    brent.optimize()
  File "C:\Python26\lib\site-packages\scipy\optimize\optimize.py", line 1347, in optimize
    xa,xb,xc,fa,fb,fc,funcalls = self.get_bracket_info()
  File "C:\Python26\lib\site-packages\scipy\optimize\optimize.py", line 1325, in get_bracket_info
    xa,xb,xc,fa,fb,fc,funcalls = bracket(func, args=args)
  File "C:\Python26\lib\site-packages\scipy\optimize\optimize.py", line 1590, in bracket
    fa = func(*(xa,)+args)
  File "C:\Python26\lib\site-packages\scipy\optimize\optimize.py", line 1652, in myfunc
    return func(p + alpha * xi)
  File "C:\Python26\lib\site-packages\scipy\optimize\optimize.py", line 97, in function_wrapper
    return function(x, *args)
  File "<string>", line 15, in error_function
  File "<string>", line 9, in generate_rho
  File "C:\Python26\lib\site-packages\numpy\core\defmatrix.py", line 290, in __mul__
    return N.dot(self, asmatrix(other))
  File "C:\Python26\lib\site-packages\numpy\core\defmatrix.py", line 241, in __array_finalize__
    if (isinstance(obj, matrix) and obj._getitem): return
SystemExit
Traceback (most recent call last):

------------------------------
2010-12-08 12:55:45.538000
------------------------------

  File "L:\python\libs\pyview\ide\codeeditor.py", line 33, in run
    exec(self.code,self._gv,self._gv)
  File "<string>", line 15, in <module>
  File "<string>", line 31, in fitDensityMatrix
  File "C:\Python26\lib\site-packages\scipy\optimize\optimize.py", line 205, in fmin
    fxr = func(xr)
  File "C:\Python26\lib\site-packages\scipy\optimize\optimize.py", line 97, in function_wrapper
    return function(x, *args)
  File "<string>", line 19, in error_function
  File "C:\Python26\lib\site-packages\numpy\core\defmatrix.py", line 290, in __mul__
    return N.dot(self, asmatrix(other))
  File "C:\Python26\lib\site-packages\numpy\core\defmatrix.py", line 241, in __array_finalize__
    if (isinstance(obj, matrix) and obj._getitem): return
SystemExit
Exception in thread Thread-110141:

------------------------------
2010-12-08 14:55:49.403000
------------------------------

Traceback (most recent call last):
  File "C:\Python26\lib\threading.py", line 525, in __bootstrap_inner
    self.run()
  File "L:\python\libs\pyview\ide\codeeditor.py", line 33, in run
    exec(self.code,self._gv,self._gv)
  File "<string>", line 1, in <module>
NameError: name 'inverse' is not defined

Traceback (most recent call last):
  File "L:\python\libs\pyview\ide\codeeditor.py", line 33, in run
    exec(self.code,self._gv,self._gv)
  File "<string>", line 1, in <module>
NameError: name 'inverse' is not defined
Exception in thread Thread-110144:
Traceback (most recent call last):
  File "C:\Python26\lib\threading.py", line 525, in __bootstrap_inner
    self.run()
  File "L:\python\libs\pyview\ide\codeeditor.py", line 33, in run
    exec(self.code,self._gv,self._gv)
  File "<string>", line 1, in <module>
AttributeError: 'matrix' object has no attribute 'inverse'

Traceback (most recent call last):
  File "L:\python\libs\pyview\ide\codeeditor.py", line 33, in run
    exec(self.code,self._gv,self._gv)
  File "<string>", line 1, in <module>
AttributeError: 'matrix' object has no attribute 'inverse'
Exception in thread Thread-110145:
Traceback (most recent call last):
  File "C:\Python26\lib\threading.py", line 525, in __bootstrap_inner
    self.run()
  File "L:\python\libs\pyview\ide\codeeditor.py", line 33, in run
    exec(self.code,self._gv,self._gv)
  File "<string>", line 1, in <module>
AttributeError: 'matrix' object has no attribute 'inv'

Traceback (most recent call last):
  File "L:\python\libs\pyview\ide\codeeditor.py", line 33, in run
    exec(self.code,self._gv,self._gv)
  File "<string>", line 1, in <module>
AttributeError: 'matrix' object has no attribute 'inv'
Exception in thread Thread-110146:
Traceback (most recent call last):
  File "C:\Python26\lib\threading.py", line 525, in __bootstrap_inner
    self.run()
  File "L:\python\libs\pyview\ide\codeeditor.py", line 33, in run
    exec(self.code,self._gv,self._gv)
  File "<string>", line 1, in <module>
AttributeError: 'matrix' object has no attribute 'inverse'

Traceback (most recent call last):
  File "L:\python\libs\pyview\ide\codeeditor.py", line 33, in run
    exec(self.code,self._gv,self._gv)
  File "<string>", line 1, in <module>
AttributeError: 'matrix' object has no attribute 'inverse'
Exception in thread Thread-110388:

------------------------------
2010-12-08 15:15:31.066000
------------------------------

Traceback (most recent call last):
  File "C:\Python26\lib\threading.py", line 525, in __bootstrap_inner
    self.run()
  File "L:\python\libs\pyview\ide\codeeditor.py", line 33, in run
    exec(self.code,self._gv,self._gv)
  File "<string>", line 1
    generateCombinations(["x","y","z"],lambda x,y:return map(y,lambda z:x+z)))
                                                       ^
SyntaxError: invalid syntax

Traceback (most recent call last):
  File "L:\python\libs\pyview\ide\codeeditor.py", line 33, in run
    exec(self.code,self._gv,self._gv)
  File "<string>", line 1
     generateCombinations(["x","y","z"],lambda x,y:return map(y,lambda z:x+z)))
                                                        ^
 SyntaxError: invalid syntax
Exception in thread Thread-110391:
Traceback (most recent call last):
  File "C:\Python26\lib\threading.py", line 525, in __bootstrap_inner
    self.run()
  File "L:\python\libs\pyview\ide\codeeditor.py", line 33, in run
    exec(self.code,self._gv,self._gv)
  File "<string>", line 1
    generateCombinations(["x","y","z"],lambda x,y:map(y,lambda z:x+z)))
                                                                      ^
SyntaxError: unexpected EOF while parsing

Traceback (most recent call last):
  File "L:\python\libs\pyview\ide\codeeditor.py", line 33, in run
    exec(self.code,self._gv,self._gv)
  File "<string>", line 1
     generateCombinations(["x","y","z"],lambda x,y:map(y,lambda z:x+z)))
                                                                       ^
 SyntaxError: unexpected EOF while parsing
Exception in thread Thread-110398:
Traceback (most recent call last):
  File "C:\Python26\lib\threading.py", line 525, in __bootstrap_inner
    self.run()
  File "L:\python\libs\pyview\ide\codeeditor.py", line 33, in run
    exec(self.code,self._gv,self._gv)
  File "<string>", line 1, in <module>
TypeError: generateCombinations() takes at least 3 arguments (2 given)

Traceback (most recent call last):
  File "L:\python\libs\pyview\ide\codeeditor.py", line 33, in run
    exec(self.code,self._gv,self._gv)
  File "<string>", line 1, in <module>
TypeError: generateCombinations() takes at least 3 arguments (2 given)
Exception in thread Thread-110401:
Traceback (most recent call last):
  File "C:\Python26\lib\threading.py", line 525, in __bootstrap_inner
    self.run()
  File "L:\python\libs\pyview\ide\codeeditor.py", line 33, in run
    exec(self.code,self._gv,self._gv)
  File "<string>", line 1, in <module>
  File "<string>", line 68, in generateCombinations
  File "<string>", line 70, in generateCombinations
  File "<string>", line 1, in <lambda>
TypeError: argument 2 to map() must support iteration

Traceback (most recent call last):
  File "L:\python\libs\pyview\ide\codeeditor.py", line 33, in run
    exec(self.code,self._gv,self._gv)
  File "<string>", line 1, in <module>
  File "<string>", line 68, in generateCombinations
  File "<string>", line 70, in generateCombinations
  File "<string>", line 1, in <lambda>
TypeError: argument 2 to map() must support iteration


------------------------------
2010-12-13 10:06:45.812000
------------------------------



------------------------------
2010-12-13 10:08:35.799000
------------------------------



------------------------------
2010-12-13 10:10:16.847000
------------------------------



------------------------------
2010-12-13 10:10:58.708000
------------------------------



------------------------------
2010-12-13 10:11:38.661000
------------------------------



------------------------------
2010-12-13 10:13:31.320000
------------------------------



------------------------------
2010-12-13 10:14:13.618000
------------------------------



------------------------------
2011-03-01 15:26:37.953000
------------------------------

Exception in thread Thread-2:
Traceback (most recent call last):
  File "C:\Python26\lib\threading.py", line 525, in __bootstrap_inner
    self.run()
  File "c:\labo\python\libs\pyview\helpers\coderunner.py", line 31, in run
    exec(code,self._lv,self._gv)
  File "C:\Labo\local-expdata\FO-C5\3rd-Run\2011_02_28\spectroscopy survey\plot_anticrossing.py", line 3, in <module>
    spectro = zeros((len(anticrossing.childrenAt(0)[0]),n))
NameError: name 'zeros' is not defined

Exception in thread Thread-4:
Traceback (most recent call last):
  File "C:\Python26\lib\threading.py", line 525, in __bootstrap_inner
    self.run()
  File "c:\labo\python\libs\pyview\helpers\coderunner.py", line 31, in run
    exec(code,self._lv,self._gv)
  File "C:\Labo\local-expdata\FO-C5\3rd-Run\2011_02_28\spectroscopy survey\plot_anticrossing.py", line 11, in <module>
    imshow(spectro,aspect = 'auto',extent = (anticrossing.column("flux")[0],anticrossing.column("flux")[n],anticrossing.childrenAt(0)[0].column("f")[0],anticrossing.childrenAt(0)[0].column("f")[-1]),interpolation = 'nearest')
NameError: name 'figure' is not defined



------------------------------
2011-03-01 15:31:12.609000
------------------------------

Exception in thread Thread-2:
Traceback (most recent call last):
  File "C:\Python26\lib\threading.py", line 525, in __bootstrap_inner
    self.run()
  File "c:\labo\python\libs\pyview\helpers\coderunner.py", line 31, in run
    exec(code,self._lv,self._gv)
  File "C:\Labo\local-expdata\FO-C5\3rd-Run\2011_02_28\spectroscopy survey\plot_anticrossing.py", line 3, in <module>
    spectro = zeros((len(anticrossing.childrenAt(0)[0]),n))
NameError: name 'zeros' is not defined

Exception in thread Thread-5:
Traceback (most recent call last):
  File "C:\Python26\lib\threading.py", line 525, in __bootstrap_inner
    self.run()
  File "c:\labo\python\libs\pyview\helpers\coderunner.py", line 31, in run
    exec(code,self._lv,self._gv)
  File "C:\Labo\python\qubit_setup\scripts\state tomography\plot_density_matrix.py", line 2, in <module>
    def plotPauliSet(measuredSpins = None,densityMatrix = None,row = None,fill = fill,lw = 1,ls = 'solid'):
NameError: name 'fill' is not defined

Exception in thread Thread-6:
Traceback (most recent call last):
  File "C:\Python26\lib\threading.py", line 525, in __bootstrap_inner
    self.run()
  File "c:\labo\python\libs\pyview\helpers\coderunner.py", line 31, in run
    exec(code,self._lv,self._gv)
  File "C:\Labo\python\qubit_setup\scripts\state tomography\plot_density_matrix.py", line 2, in <module>
    def plotPauliSet(measuredSpins = None,densityMatrix = None,row = None,fill = fill,lw = 1,ls = 'solid'):
NameError: name 'fill' is not defined

Exception in thread Thread-9:
Traceback (most recent call last):
  File "C:\Python26\lib\threading.py", line 525, in __bootstrap_inner
    self.run()
  File "c:\labo\python\libs\pyview\helpers\coderunner.py", line 31, in run
    exec(code,self._lv,self._gv)
  File "C:\Labo\local-expdata\FO-C5\3rd-Run\2011_02_28\spectroscopy survey\plot_anticrossing.py", line 9, in <module>
    figure("anticrossing")
NameError: name 'figure' is not defined

Exception in thread Thread-11:
Traceback (most recent call last):
  File "C:\Python26\lib\threading.py", line 525, in __bootstrap_inner
    self.run()
  File "c:\labo\python\libs\pyview\helpers\coderunner.py", line 31, in run
    exec(code,self._lv,self._gv)
  File "C:\Labo\local-expdata\FO-C5\3rd-Run\2011_02_28\spectroscopy survey\plot_anticrossing.py", line 10, in <module>
    clf()
NameError: name 'clf' is not defined

Exception in thread Thread-13:
Traceback (most recent call last):
  File "C:\Python26\lib\threading.py", line 525, in __bootstrap_inner
    self.run()
  File "c:\labo\python\libs\pyview\helpers\coderunner.py", line 31, in run
    exec(code,self._lv,self._gv)
  File "C:\Labo\local-expdata\FO-C5\3rd-Run\2011_02_28\spectroscopy survey\plot_anticrossing.py", line 10, in <module>
    clf()
NameError: name 'clf' is not defined

Exception in thread Thread-15:
Traceback (most recent call last):
  File "C:\Python26\lib\threading.py", line 525, in __bootstrap_inner
    self.run()
  File "c:\labo\python\libs\pyview\helpers\coderunner.py", line 31, in run
    exec(code,self._lv,self._gv)
  File "C:\Labo\local-expdata\FO-C5\3rd-Run\2011_02_28\spectroscopy survey\plot_anticrossing.py", line 10, in <module>
    clf()
NameError: name 'clf' is not defined

Exception in thread Thread-16:
Traceback (most recent call last):
  File "C:\Python26\lib\threading.py", line 525, in __bootstrap_inner
    self.run()
  File "c:\labo\python\libs\pyview\helpers\coderunner.py", line 31, in run
    exec(code,self._lv,self._gv)
  File "C:\Labo\local-expdata\FO-C5\3rd-Run\2011_02_28\spectroscopy survey\plot_anticrossing.py", line 1, in <module>
    n = len(anticrossing)
ImportError: No module named mathplotlib

Exception in thread Thread-17:
Traceback (most recent call last):
  File "C:\Python26\lib\threading.py", line 525, in __bootstrap_inner
    self.run()
  File "c:\labo\python\libs\pyview\helpers\coderunner.py", line 31, in run
    exec(code,self._lv,self._gv)
  File "C:\Labo\local-expdata\FO-C5\3rd-Run\2011_02_28\spectroscopy survey\plot_anticrossing.py", line 1, in <module>
    n = len(anticrossing)
ImportError: No module named mathplotlib.mlab

Exception in thread Thread-18:
Traceback (most recent call last):
  File "C:\Python26\lib\threading.py", line 525, in __bootstrap_inner
    self.run()
  File "c:\labo\python\libs\pyview\helpers\coderunner.py", line 31, in run
    exec(code,self._lv,self._gv)
  File "C:\Labo\local-expdata\FO-C5\3rd-Run\2011_02_28\spectroscopy survey\plot_anticrossing.py", line 1, in <module>
    n = len(anticrossing)
ImportError: No module named mathplotlib

Exception in thread Thread-20:
Traceback (most recent call last):
  File "C:\Python26\lib\threading.py", line 525, in __bootstrap_inner
    self.run()
  File "c:\labo\python\libs\pyview\helpers\coderunner.py", line 31, in run
    exec(code,self._lv,self._gv)
  File "C:\Labo\local-expdata\FO-C5\3rd-Run\2011_02_28\spectroscopy survey\plot_anticrossing.py", line 9, in <module>
    figure("anticrossing")
TypeError: 'module' object is not callable

Exception in thread Thread-22:
Traceback (most recent call last):
  File "C:\Python26\lib\threading.py", line 525, in __bootstrap_inner
    self.run()
  File "c:\labo\python\libs\pyview\helpers\coderunner.py", line 31, in run
    exec(code,self._lv,self._gv)
  File "C:\Labo\local-expdata\FO-C5\3rd-Run\2011_02_28\spectroscopy survey\plot_anticrossing.py", line 10, in <module>
    clf()
NameError: name 'clf' is not defined

Traceback (most recent call last):
  File "c:\labo\python\libs\pyview\helpers\instrumentsmanager.py", line 268, in initInstrument
    instrument.initialize(*args,**kwargs)
  File "C:\Labo\python\qubit_setup\instruments\qubit.py", line 638, in initialize
    if self._register.hasKey(k):
AttributeError: 'NoneType' object has no attribute 'hasKey'
Traceback (most recent call last):
  File "c:\labo\python\libs\pyview\helpers\instrumentsmanager.py", line 268, in initInstrument
    instrument.initialize(*args,**kwargs)
  File "C:\Labo\python\qubit_setup\instruments\qubit.py", line 638, in initialize
    if self._register.hasKey(k):
AttributeError: 'NoneType' object has no attribute 'hasKey'
